Workbook

Sheet How to use
A1: WeQuote CRM — Phase 1 QA checklist
A2: Source | B2: Derived from WeQuote-CRM-Phase-1-PRD.html — acceptance criteria (§B3), requirements (§B2) and the delivery gate (§A14).
A4: Sheets | B4: Summary · Delivery gate · Phase 1A / 1B / 1C · Recipe coverage · Regression
A5: Fill in | B5: Status onwards. Everything left of Status describes the test and should not be edited.
A6: Status values | B6: Not run · Pass · Fail · Blocked · N/A
A7: What blocks a release | B7: Fail, Blocked and Not run block. Pass and N/A do not.
A8: Using N/A | B8: Only for a test that cannot apply to this release. It must carry a reason in Notes and a name in 'Waiver approved by'. The Summary counts unapproved N/A separately.
A9: Applies from | B9: On Regression, the earliest release a rule can be tested in. A Phase 1A gate only counts rules that apply from Phase 1A.
A10: Method | B10: Manual, Automated or Both. The PRD requires the resolver, tenancy and duplicate tests to be automated — record the CI link under Evidence.
A11: Priority | B11: P1 must pass before the release ships. P2 needs a named owner to accept any exception. P3 is optional.
A12: Date format | B12: YYYY-MM-DD
A14: Example row | B14: Status: Fail · Actual result: Deal stayed in Qualified · Build: 1A-rc3 · Environment: Staging · Browser: Chrome 141 / macOS · Test data: D-0348 · Evidence: jira/WQ-1183 · Defect ID: WQ-1183 · Tester: KW · Date: 2026-09-04
A16: Assumptions | B16: 1. Tests marked 'cond. D1' apply only if backward Deal movement is approved.
B17: 2. D5 tests have no fixed expected result until the over-quota and sales-order ruling is recorded.
B18: 3. D7 decides whose approval threshold applies; the approval boundary tests inherit that answer.
B19: 4. Phase 1B and 1C assume the preceding release passed its own P1 tests.

Sheet Test Plan
A1: Test plan — WeQuote CRM Phase 1
A2: How this release is tested, by whom, in what order, and what has to be true before it ships.
A4: Objectives
B5: • Prove the Deal stage is always derived from quotes and can never be typed in.
B6: • Prove one customer account can never read or change another's records.
B7: • Prove an Automation cannot approve, send, accept, or decide Won or Lost.
B8: • Prove money figures — signed value, change orders, margin — agree with the quotes behind them.
B9: • Prove each release can ship on its own without waiting for the next.
A11: In scope
B12: • Lead, Deal, Customer, Company and Activity records.
B13: • Quote-to-stage logic, alternative groups and change orders.
B14: • Deal value and the four margin figures.
B15: • Managed recipes, their settings, scheduling and results.
B16: • The advanced builder: catalogue, editing, testing, publishing, required work.
B17: • Company-level visibility and account isolation.
A19: Out of scope
B20: • Forecast dashboards and weighted probability — Phase 2.
B21: • Customer-created custom stages — Phase 2.
B22: • Fully custom pipelines — Phase 3.
B23: • Public web-to-lead forms — deferred.
B24: • Zoho, QuickBooks and Xero behaviour beyond the coexistence rule in §C3.
A26: Test levels
B27: • Component: stage logic, quote-inclusion test, value arithmetic — automated.
B28: • Integration: quote event to Deal update to Automation run — automated.
B29: • System: the end-to-end journeys on the Use Case Coverage sheet — manual.
B30: • UAT: the same journeys run by Sales and an Admin on staging.
B31: • Regression: the six locked rules, re-run in full before every release.
A33: Approach
B34: • Automate anything the PRD names as automated: the precedence ladder, the quote-inclusion clauses, both revision flags, idempotency and account isolation.
B35: • Everything else is manual, with evidence attached.
B36: • Each test records its Method so automated coverage can be proven, not asserted.
A38: Environment
B39: • Staging, refreshed from a masked production copy before each release cycle.
B40: • Build or commit recorded against every executed test.
B41: • Timed recipes need the work queue running; note in Actual result if it was not.
A43: Test accounts
B44: • Audio Vision Group with at least three companies, for company-scope tests.
B45: • A second unrelated account, for isolation tests.
B46: • One Sales user limited to one company, one manager across all, one user with no CRM access.
B47: • An approver distinct from the quote owner, for the high-value approval tests.
...

Sheet Summary
A1: Release gates
A2: A release is clear when no P1 test is Fail, Blocked or Not run. Pass and N/A do not block; an N/A needs a reason and an approver.
A4: Release | B4: Total | C4: Pass | D4: Fail | E4: Blocked | F4: N/A | G4: Not run | H4: P1 blocking | I4: Verdict
A5: Phase 1A | B5: =COUNTA('Phase 1A'!$A$5:$A$58) | C5: =COUNTIF('Phase 1A'!$K$5:$K$58,"Pass") | D5: =COUNTIF('Phase 1A'!$K$5:$K$58,"Fail") | E5: =COUNTIF('Phase 1A'!$K$5:$K$58,"Blocked") | F5: =COUNTIF('Phase 1A'!$K$5:$K$58,"N/A") | G5: =COUNTIF('Phase 1A'!$K$5:$K$58,"Not run") | H5: =COUNTIFS('Phase 1A'!$E$5:$E$58,"P1")-COUNTIFS('Phase 1A'!$E$5:$E$58,"P1",'Phase 1A'!$K$5:$K$58,"Pass")-COUNTIFS('Phase 1A'!$E$5:$E$58,"P1",'Phase 1A'!$K$5:$K$58,"N/A")+COUNTIFS(Regression!$C$5:$C$10,"Phase 1A",Regression!$E$5:$E$10,"P1")-COUNTIFS(Regression!$C$5:$C$10,"Phase 1A",Regression!$E$5:$E$10,"P1",Regression!$K$5:$K$10,"Pass")-COUNTIFS(Regression!$C$5:$C$10,"Phase 1A",Regression!$E$5:$E$10,"P1",Regression!$K$5:$K$10,"N/A") | I5: =IF(H5=0,"Clear to ship","Blocked — "&H5&" P1 outstanding")
A6: Phase 1B | B6: =COUNTA('Phase 1B'!$A$5:$A$29) | C6: =COUNTIF('Phase 1B'!$K$5:$K$29,"Pass") | D6: =COUNTIF('Phase 1B'!$K$5:$K$29,"Fail") | E6: =COUNTIF('Phase 1B'!$K$5:$K$29,"Blocked") | F6: =COUNTIF('Phase 1B'!$K$5:$K$29,"N/A") | G6: =COUNTIF('Phase 1B'!$K$5:$K$29,"Not run") | H6: =COUNTIFS('Phase 1B'!$E$5:$E$29,"P1")-COUNTIFS('Phase 1B'!$E$5:$E$29,"P1",'Phase 1B'!$K$5:$K$29,"Pass")-COUNTIFS('Phase 1B'!$E$5:$E$29,"P1",'Phase 1B'!$K$5:$K$29,"N/A")+COUNTIFS(Regression!$C$5:$C$10,"Phase 1A",Regression!$E$5:$E$10,"P1")-COUNTIFS(Regression!$C$5:$C$10,"Phase 1A",Regression!$E$5:$E$10,"P1",Regression!$K$5:$K$10,"Pass")-COUNTIFS(Regression!$C$5:$C$10,"Phase 1A",Regression!$E$5:$E$10,"P1",Regression!$K$5:$K$10,"N/A") | I6: =IF(H6=0,"Clear to ship","Blocked — "&H6&" P1 outstanding")
A7: Phase 1C | B7: =COUNTA('Phase 1C'!$A$5:$A$40) | C7: =COUNTIF('Phase 1C'!$K$5:$K$40,"Pass") | D7: =COUNTIF('Phase 1C'!$K$5:$K$40,"Fail") | E7: =COUNTIF('Phase 1C'!$K$5:$K$40,"Blocked") | F7: =COUNTIF('Phase 1C'!$K$5:$K$40,"N/A") | G7: =COUNTIF('Phase 1C'!$K$5:$K$40,"Not run") | H7: =COUNTIFS('Phase 1C'!$E$5:$E$40,"P1")-COUNTIFS('Phase 1C'!$E$5:$E$40,"P1",'Phase 1C'!$K$5:$K$40,"Pass")-COUNTIFS('Phase 1C'!$E$5:$E$40,"P1",'Phase 1C'!$K$5:$K$40,"N/A")+COUNTIFS(Regression!$C$5:$C$10,"Phase 1A",Regression!$E$5:$E$10,"P1")-COUNTIFS(Regression!$C$5:$C$10,"Phase 1A",Regression!$E$5:$E$10,"P1",Regression!$K$5:$K$10,"Pass")-COUNTIFS(Regression!$C$5:$C$10,"Phase 1A",Regression!$E$5:$E$10,"P1",Regression!$K$5:$K$10,"N/A")+COUNTIFS(Regression!$C$5:$C$10,"Phase 1C",Regression!$E$5:$E$10,"P1")-COUNTIFS(Regression!$C$5:$C$10,"Phase 1C",Regression!$E$5:$E$10,"P1",Regression!$K$5:$K$10,"Pass")-COUNTIFS(Regression!$C$5:$C$10,"Phase 1C",Regression!$E$5:$E$10,"P1",Regression!$K$5:$K$10,"N/A") | I7: =IF(H7=0,"Clear to ship","Blocked — "&H7&" P1 outstanding")
A8: Recipe coverage | B8: =108 | C8: =COUNTIF('Recipe coverage'!$E$5:$M$16,"Pass") | D8: =COUNTIF('Recipe coverage'!$E$5:$M$16,"Fail") | E8: =COUNTIF('Recipe coverage'!$E$5:$M$16,"Blocked") | F8: =COUNTIF('Recipe coverage'!$E$5:$M$16,"N/A") | G8: =COUNTIF('Recipe coverage'!$E$5:$M$16,"Not run") | H8: =D8+E8+G8 | I8: =IF(H8=0,"Clear to ship","Blocked — "&H8&" checks outstanding")
A9: Phase 1 programme | B9: =SUM(B5:B8) | C9: =SUM(C5:C8) | D9: =SUM(D5:D8) | E9: =SUM(E5:E8) | F9: =SUM(F5:F8) | G9: =SUM(G5:G8) | H9: =SUM(H5:H8) | I9: =IF(H9=0,"Entire Phase 1 clear","Blocked — "&H9&" P1 outstanding across the programme")
A11: N/A hygiene
A12: N/A without a waiver approver | B12: =(COUNTIFS('Phase 1A'!$K$5:$K$58,"N/A")-COUNTIFS('Phase 1A'!$K$5:$K$58,"N/A",'Phase 1A'!$S$5:$S$58,"<>"))+(COUNTIFS('Phase 1B'!$K$5:$K$29,"N/A")-COUNTIFS('Phase 1B'!$K$5:$K$29,"N/A",'Phase 1B'!$S$5:$S$29,"<>"))+(COUNTIFS('Phase 1C'!$K$5:$K$40,"N/A")-COUNTIFS('Phase 1C'!$K$5:$K$40,"N/A",'Phase 1C'!$S$5:$S$40,"<>"))+(COUNTIFS('Regression'!$K$5:$K$10,"N/A")-COUNTIFS('Regression'!$K$5:$K$10,"N/A",'Regression'!$S$5:$S$10,"<>"))
A13: Every N/A must carry a reason in Notes and an approver in 'Waiver approved by'.

Sheet Delivery gate
A1: Delivery gate — Phase 1
A2: Extracted from §A14 of the PRD. Each release has its own gate; blocking items stop that release only.
A4: ID | B4: Release | C4: Area | D4: Item | E4: Role | F4: Gate | G4: Owner | H4: Status | I4: Target date | J4: Evidence / link
A5: G-01 | B5: Phase 1A | C5: Decisions closed | D5: D1 — do Deals move backwards? Until this is answered, FR-24 is not committed scope. | E5: Product | F5: Blocking | H5: Not started
A6: G-02 | B6: Phase 1A | C6: Decisions closed | D6: D2 — Zoho coexistence. Deals stay switched off for Zoho-connected organisations until agreed. | E6: Product + CTO | F6: Blocking | H6: Not started
A7: G-03 | B7: Phase 1A | C7: Decisions closed | D7: D4 — is the CRM company the existing Trading Name, or a new record? | E7: Product + Eng | F7: Blocking | H7: Not started
A8: G-04 | B8: Phase 1A | C8: Decisions closed | D8: D5 — do over-quota quotes and sales orders count toward a Deal stage? | E8: Product | F8: Blocking | H8: Not started
A9: G-05 | B9: Phase 1A | C9: Decisions closed | D9: D6 — does raising a change order follow the quote review path? | E9: Product | F9: Blocking | H9: Not started
A10: G-06 | B10: Phase 1A | C10: Decisions closed | D10: D3 — why is today's activity timeline unused? Research complete, findings applied to the design. | E10: Product + Design | F10: Blocking | H10: Not started
A11: G-07 | B11: Phase 1A | C11: Data | D11: Quote stage history extended to record the review stages it currently cannot. | E11: Data | F11: Blocking | H11: Not started
A12: G-08 | B12: Phase 1A | C12: Data | D12: Activity timeline carries an organisation column, filled in for existing rows. | E12: Data | F12: Blocking | H12: Not started
A13: G-09 | B13: Phase 1A | C13: Data | D13: Owning company assigned to existing quotes that have none. | E13: Data | F13: Blocking | H13: Not started
A14: G-10 | B14: Phase 1A | C14: Data | D14: Ruling recorded on whether Deals are created for existing quotes, or only for new work. | E14: Product + Eng | F14: Blocking | H14: Not started
A15: G-11 | B15: Phase 1A | C15: Data | D15: Default Lead states and disqualify reasons seeded per organisation. | E15: Data | F15: Track | H15: Not started
A16: G-12 | B16: Phase 1A | C16: Build | D16: Stage logic derives every stage; no screen lets a person set one. | E16: Engineering | F16: Blocking | H16: Not started
... A44: G-40 | B44: Phase 1C | C44: Handoff | D44: "Open as an editable copy" documented as one-way, with no promise of returning to the simple form. | E44: Design | F44: Track | H44: Not started
A46: Gate by release
A47: Release | B47: Total | C47: Done | D47: Blocking outstanding | E47: Verdict
A48: Phase 1A | B48: =COUNTIF($B$5:$B$44,"Phase 1A") | C48: =COUNTIFS($B$5:$B$44,"Phase 1A",$H$5:$H$44,"Done") | D48: =COUNTIFS($B$5:$B$44,"Phase 1A",$F$5:$F$44,"Blocking")-COUNTIFS($B$5:$B$44,"Phase 1A",$F$5:$F$44,"Blocking",$H$5:$H$44,"Done") | E48: =IF(D48=0,"Gate clear","Blocked — "&D48&" outstanding")
A49: Phase 1B | B49: =COUNTIF($B$5:$B$44,"Phase 1B") | C49: =COUNTIFS($B$5:$B$44,"Phase 1B",$H$5:$H$44,"Done") | D49: =COUNTIFS($B$5:$B$44,"Phase 1B",$F$5:$F$44,"Blocking")-COUNTIFS($B$5:$B$44,"Phase 1B",$F$5:$F$44,"Blocking",$H$5:$H$44,"Done") | E49: =IF(D49=0,"Gate clear","Blocked — "&D49&" outstanding")
A50: Phase 1C | B50: =COUNTIF($B$5:$B$44,"Phase 1C") | C50: =COUNTIFS($B$5:$B$44,"Phase 1C",$H$5:$H$44,"Done") | D50: =COUNTIFS($B$5:$B$44,"Phase 1C",$F$5:$F$44,"Blocking")-COUNTIFS($B$5:$B$44,"Phase 1C",$F$5:$F$44,"Blocking",$H$5:$H$44,"Done") | E50: =IF(D50=0,"Gate clear","Blocked — "&D50&" outstanding")
A51: Rows missing Owner or Target date | B51: =COUNTIF($G$5:$G$44,"")+COUNTIF($I$5:$I$44,"")
A52: Every gate row needs a named owner and a target date before the release is planned.

Sheet Traceability
A1: Traceability — locked rule to evidence
A2: One row per link. Status is live: it reads the QA case's own result. A rule is only proven when every linked case passes.
A4: Rule | B4: Statement | C4: Requirement | D4: Acceptance criterion | E4: QA sheet | F4: QA case | G4: Delivery gate | H4: Applies from | I4: Live status | J4: Gap / note
A5: 1 | B5: Creating the first related quote moves the Deal from Qualified to In Progress. | C5: — (no FR states the transition) | D5: AC-DEAL-01 | E5: Phase 1A | F5: 1A-08 | G5: G-12 | H5: Phase 1A | I5: =IFERROR(INDEX('Phase 1A'!$K$5:$K$58,MATCH("1A-08",'Phase 1A'!$A$5:$A$58,0)),"not found") | J5: GAP: the transition is stated in §A6 and tested, but no functional requirement carries it. Add one, or cite §A6 explicitly.
E6: Regression | F6: REG-01 | I6: =IFERROR(INDEX('Regression'!$K$5:$K$10,MATCH("REG-01",'Regression'!$A$5:$A$10,0)),"not found")
A7: 2 | B7: Any relevant quote being accepted makes the Deal Won. Remaining groups change the signed value, never the stage. | C7: FR-16, FR-17 | D7: AC-DEAL-01, AC-DEAL-07 | E7: Phase 1A | F7: 1A-14 | G7: G-17 | H7: Phase 1A | I7: =IFERROR(INDEX('Phase 1A'!$K$5:$K$58,MATCH("1A-14",'Phase 1A'!$A$5:$A$58,0)),"not found")
E8: Phase 1A | F8: 1A-15 | I8: =IFERROR(INDEX('Phase 1A'!$K$5:$K$58,MATCH("1A-15",'Phase 1A'!$A$5:$A$58,0)),"not found")
E9: Phase 1A | F9: 1A-16 | I9: =IFERROR(INDEX('Phase 1A'!$K$5:$K$58,MATCH("1A-16",'Phase 1A'!$A$5:$A$58,0)),"not found")
E10: Phase 1A | F10: 1A-17 | I10: =IFERROR(INDEX('Phase 1A'!$K$5:$K$58,MATCH("1A-17",'Phase 1A'!$A$5:$A$58,0)),"not found")
E11: Regression | F11: REG-02 | I11: =IFERROR(INDEX('Regression'!$K$5:$K$10,MATCH("REG-02",'Regression'!$A$5:$A$10,0)),"not found")
A12: 3 | B12: Sales supplies the loss reason. Sales does not decide the Lost outcome; the system derives it. | C12: — (FR-17 covers Won and Archived only) | D12: AC-DEAL-01 | E12: Phase 1A | F12: 1A-19 | G12: G-17 | H12: Phase 1A | I12: =IFERROR(INDEX('Phase 1A'!$K$5:$K$58,MATCH("1A-19",'Phase 1A'!$A$5:$A$58,0)),"not found") | J12: GAP: no FR separates deriving the outcome from supplying the reason. §A6 and §A7 both state it; a requirement should too.
E13: Regression | F13: REG-03 | I13: =IFERROR(INDEX('Regression'!$K$5:$K$10,MATCH("REG-03",'Regression'!$A$5:$A$10,0)),"not found")
A14: 4 | B14: Testing is optional. Only a real conflict blocks publishing. | C14: FR-13 | D14: AC-BLD-10 | E14: Phase 1C | F14: 1C-18 | G14: G-36 | H14: Phase 1C | I14: =IFERROR(INDEX('Phase 1C'!$K$5:$K$40,MATCH("1C-18",'Phase 1C'!$A$5:$A$40,0)),"not found")
E15: Regression | F15: REG-04 | I15: =IFERROR(INDEX('Regression'!$K$5:$K$10,MATCH("REG-04",'Regression'!$A$5:$A$10,0)),"not found")
A16: 5 | B16: A Phase 2 custom stage receives the identical core block library wherever it sits. | C16: FR-06, FR-33 | D16: AC-BLD-05 | E16: Phase 1C | F16: 1C-06 | G16: G-35, G-38 | H16: Phase 2 | I16: =IFERROR(INDEX('Phase 1C'!$K$5:$K$40,MATCH("1C-06",'Phase 1C'!$A$5:$A$40,0)),"not found") | J16: REG-05 cannot run before Phase 2. It is excluded from the Phase 1 gates by its Applies from value.
E17: Phase 1C | F17: 1C-09 | I17: =IFERROR(INDEX('Phase 1C'!$K$5:$K$40,MATCH("1C-09",'Phase 1C'!$A$5:$A$40,0)),"not found")
E18: Regression | F18: REG-05 | I18: =IFERROR(INDEX('Regression'!$K$5:$K$10,MATCH("REG-05",'Regression'!$A$5:$A$10,0)),"not found")
A19: 6 | B19: A protected quote lifecycle event is never an ordinary Automation action. | C19: FR-08 | D19: AC-BLD-07 | E19: Phase 1C | F19: 1C-08 | G19: G-12 | H19: Phase 1A | I19: =IFERROR(INDEX('Phase 1C'!$K$5:$K$40,MATCH("1C-08",'Phase 1C'!$A$5:$A$40,0)),"not found")
E20: Regression | F20: REG-06 | I20: =IFERROR(INDEX('Regression'!$K$5:$K$10,MATCH("REG-06",'Regression'!$A$5:$A$10,0)),"not found")
A22: Linked cases passing | C22: =COUNTIF(I5:I20,"Pass")&" of "&COUNTA(I5:I20)
A23: Requirement gaps | C23: =COUNTIF(J5:J20,"GAP*")&" locked rules have no functional requirement"
B25: A locked rule is only safe once every linked QA case passes AND its delivery gate item is Done. The two gaps are documentation gaps, not test gaps — both rules are tested.

Sheet Use Case Coverage
A1: Use case coverage
A2: End-to-end journeys, each mapped to the granular cases that make it up. Coverage is live: it reads those cases' results.
A4: ID | B4: Use case | C4: Phase | D4: Persona | E4: Journey | F4: Test IDs | G4: Cases | H4: Passing | I4: Coverage | J4: Notes
A5: UC-01 | B5: Lead to first quote | C5: Phase 1A | D5: Sales | E5: New Lead → duplicate check → customer linked → convert → Deal in Qualified → create first quote → In Progress | F5: 1A-01, 1A-02, 1A-08 | G5: 3 | H5: =COUNTIFS('Phase 1A'!$A$5:$A$58,"1A-01",'Phase 1A'!$K$5:$K$58,"Pass")+COUNTIFS('Phase 1A'!$A$5:$A$58,"1A-02",'Phase 1A'!$K$5:$K$58,"Pass")+COUNTIFS('Phase 1A'!$A$5:$A$58,"1A-08",'Phase 1A'!$K$5:$K$58,"Pass") | I5: =IF(H5=G5,"Fully covered",IF(H5=0,"Not started","Partial — "&H5&" of "&G5)
A6: UC-02 | B6: Full review path | C6: Phase 1A | D6: Sales + Reviewer | E6: In Progress → submit → In Review → pass → Passed Review → send → Sent | F6: 1A-09, 1A-10, 1A-11 | G6: 3 | H6: =COUNTIFS('Phase 1A'!$A$5:$A$58,"1A-09",'Phase 1A'!$K$5:$K$58,"Pass")+COUNTIFS('Phase 1A'!$A$5:$A$58,"1A-10",'Phase 1A'!$K$5:$K$58,"Pass")+COUNTIFS('Phase 1A'!$A$5:$A$58,"1A-11",'Phase 1A'!$K$5:$K$58,"Pass") | I6: =IF(H6=G6,"Fully covered",IF(H6=0,"Not started","Partial — "&H6&" of "&G6)
A7: UC-03 | B7: No-review path | C7: Phase 1A | D7: Sales | E7: Review disabled → In Progress → send → Sent, skipping both review stages | F7: 1A-12 | G7: 1 | H7: =COUNTIFS('Phase 1A'!$A$5:$A$58,"1A-12",'Phase 1A'!$K$5:$K$58,"Pass") | I7: =IF(H7=G7,"Fully covered",IF(H7=0,"Not started","Partial — "&H7&" of "&G7)
A8: UC-04 | B8: Changes requested | C8: Phase 1A | D8: Reviewer | E8: In Review → changes requested → back to In Progress → resubmit | F8: 1A-13, 1A-09 | G8: 2 | H8: =COUNTIFS('Phase 1A'!$A$5:$A$58,"1A-13",'Phase 1A'!$K$5:$K$58,"Pass")+COUNTIFS('Phase 1A'!$A$5:$A$58,"1A-09",'Phase 1A'!$K$5:$K$58,"Pass") | I8: =IF(H8=G8,"Fully covered",IF(H8=0,"Not started","Partial — "&H8&" of "&G8)
A9: UC-05 | B9: Client engagement | C9: Phase 1A | D9: Sales | E9: Three quotes sent → client opens two → Deal card shows 2 of 3 viewed | F9: 1A-31, 1A-30, 1A-32 | G9: 3 | H9: =COUNTIFS('Phase 1A'!$A$5:$A$58,"1A-31",'Phase 1A'!$K$5:$K$58,"Pass")+COUNTIFS('Phase 1A'!$A$5:$A$58,"1A-30",'Phase 1A'!$K$5:$K$58,"Pass")+COUNTIFS('Phase 1A'!$A$5:$A$58,"1A-32",'Phase 1A'!$K$5:$K$58,"Pass") | I9: =IF(H9=G9,"Fully covered",IF(H9=0,"Not started","Partial — "&H9&" of "&G9)
A10: UC-06 | B10: Win the deal | C10: Phase 1A | D10: Sales | E10: Alternative group of three → accept one → siblings rejected → Deal Won → value locked | F10: 1A-16, 1A-14, 1A-45 | G10: 3 | H10: =COUNTIFS('Phase 1A'!$A$5:$A$58,"1A-16",'Phase 1A'!$K$5:$K$58,"Pass")+COUNTIFS('Phase 1A'!$A$5:$A$58,"1A-14",'Phase 1A'!$K$5:$K$58,"Pass")+COUNTIFS('Phase 1A'!$A$5:$A$58,"1A-45",'Phase 1A'!$K$5:$K$58,"Pass") | I10: =IF(H10=G10,"Fully covered",IF(H10=0,"Not started","Partial — "&H10&" of "&G10)
A11: UC-07 | B11: Lose the deal | C11: Phase 1A | D11: Sales | E11: All quotes expire → Lost derived → Sales supplies the loss reason | F11: 1A-19 | G11: 1 | H11: =COUNTIFS('Phase 1A'!$A$5:$A$58,"1A-19",'Phase 1A'!$K$5:$K$58,"Pass") | I11: =IF(H11=G11,"Fully covered",IF(H11=0,"Not started","Partial — "&H11&" of "&G11)
A12: UC-08 | B12: Work called off | C12: Phase 1A | D12: Sales | E12: All quotes cancelled → Deal Archived, not Lost | F12: 1A-18 | G12: 1 | H12: =COUNTIFS('Phase 1A'!$A$5:$A$58,"1A-18",'Phase 1A'!$K$5:$K$58,"Pass") | I12: =IF(H12=G12,"Fully covered",IF(H12=0,"Not started","Partial — "&H12&" of "&G12)
A13: UC-09 | B13: Additive versus competing | C13: Phase 1A | D13: Sales | E13: Two independent quotes add up; two grouped quotes compete | F13: 1A-34, 1A-35, 1A-37 | G13: 3 | H13: =COUNTIFS('Phase 1A'!$A$5:$A$58,"1A-34",'Phase 1A'!$K$5:$K$58,"Pass")+COUNTIFS('Phase 1A'!$A$5:$A$58,"1A-35",'Phase 1A'!$K$5:$K$58,"Pass")+COUNTIFS('Phase 1A'!$A$5:$A$58,"1A-37",'Phase 1A'!$K$5:$K$58,"Pass") | I13: =IF(H13=G13,"Fully covered",IF(H13=0,"Not started","Partial — "&H13&" of "&G13)
A14: UC-10 | B14: Vary sold work | C14: Phase 1A | D14: Sales + Finance | E14: Accepted quote → raise change order → client signs → value updated, stage unchanged | F14: 1A-38, 1A-40, 1A-42 | G14: 3 | H14: =COUNTIFS('Phase 1A'!$A$5:$A$58,"1A-38",'Phase 1A'!$K$5:$K$58,"Pass")+COUNTIFS('Phase 1A'!$A$5:$A$58,"1A-40",'Phase 1A'!$K$5:$K$58,"Pass")+COUNTIFS('Phase 1A'!$A$5:$A$58,"1A-42",'Phase 1A'!$K$5:$K$58,"Pass") | I14: =IF(H14=G14,"Fully covered",IF(H14=0,"Not started","Partial — "&H14&" of "&G14)
A15: UC-11 | B15: Multi-company working | C15: Phase 1A | D15: Manager | E15: Audio Vision manager sees permitted companies only; scoped Automation runs for one branch | F15: 1A-47, 1B-04 | G15: 2 | H15: =COUNTIFS('Phase 1A'!$A$5:$A$58,"1A-47",'Phase 1A'!$K$5:$K$58,"Pass")+COUNTIFS('Phase 1B'!$A$5:$A$29,"1B-04",'Phase 1B'!$K$5:$K$29,"Pass") | I15: =IF(H15=G15,"Fully covered",IF(H15=0,"Not started","Partial — "&H15&" of "&G15)
A16: UC-12 | B16: Switch on a recipe | C16: Phase 1B | D16: Admin | E16: Choose a recipe → set owner, days and scope → activate → it fires and writes to the Deal card | F16: 1B-01, 1B-02, 1B-20 | G16: 3 | H16: =COUNTIFS('Phase 1B'!$A$5:$A$29,"1B-01",'Phase 1B'!$K$5:$K$29,"Pass")+COUNTIFS('Phase 1B'!$A$5:$A$29,"1B-02",'Phase 1B'!$K$5:$K$29,"Pass")+COUNTIFS('Phase 1B'!$A$5:$A$29,"1B-20",'Phase 1B'!$K$5:$K$29,"Pass") | I16: =IF(H16=G16,"Fully covered",IF(H16=0,"Not started","Partial — "&H16&" of "&G16)
A17: UC-13 | B17: Chase a sent quote | C17: Phase 1B | D17: Sales | E17: Quote sent → wait three working days → follow-up note created and visible | F17: 1B-09, 1B-21 | G17: 2 | H17: =COUNTIFS('Phase 1B'!$A$5:$A$29,"1B-09",'Phase 1B'!$K$5:$K$29,"Pass")+COUNTIFS('Phase 1B'!$A$5:$A$29,"1B-21",'Phase 1B'!$K$5:$K$29,"Pass") | I17: =IF(H17=G17,"Fully covered",IF(H17=0,"Not started","Partial — "&H17&" of "&G17)
A18: UC-14 | B18: High-value approval | C18: Phase 1B | D18: Sales + Approver | E18: Quote passes review above threshold → approval note raised to the approver | F18: 1B-16, 1B-17 | G18: 2 | H18: =COUNTIFS('Phase 1B'!$A$5:$A$29,"1B-16",'Phase 1B'!$K$5:$K$29,"Pass")+COUNTIFS('Phase 1B'!$A$5:$A$29,"1B-17",'Phase 1B'!$K$5:$K$29,"Pass") | I18: =IF(H18=G18,"Fully covered",IF(H18=0,"Not started","Partial — "&H18&" of "&G18)
A19: UC-15 | B19: Draft to publish | C19: Phase 1C | D19: Admin | E19: Open → edit → save draft → test → validate → publish → history recorded | F19: 1C-12, 1C-16, 1C-20, 1C-30 | G19: 4 | H19: =COUNTIFS('Phase 1C'!$A$5:$A$40,"1C-12",'Phase 1C'!$K$5:$K$40,"Pass")+COUNTIFS('Phase 1C'!$A$5:$A$40,"1C-16",'Phase 1C'!$K$5:$K$40,"Pass")+COUNTIFS('Phase 1C'!$A$5:$A$40,"1C-20",'Phase 1C'!$K$5:$K$40,"Pass")+COUNTIFS('Phase 1C'!$A$5:$A$40,"1C-30",'Phase 1C'!$K$5:$K$40,"Pass") | I19: =IF(H19=G19,"Fully covered",IF(H19=0,"Not started","Partial — "&H19&" of "&G19)
A20: UC-16 | B20: Blocked publish | C20: Phase 1C | D20: Admin | E20: Introduce a conflict → publishing refused with the step named → fix → publish succeeds | F20: 1C-21, 1C-20 | G20: 2 | H20: =COUNTIFS('Phase 1C'!$A$5:$A$40,"1C-21",'Phase 1C'!$K$5:$K$40,"Pass")+COUNTIFS('Phase 1C'!$A$5:$A$40,"1C-20",'Phase 1C'!$K$5:$K$40,"Pass") | I20: =IF(H20=G20,"Fully covered",IF(H20=0,"Not started","Partial — "&H20&" of "&G20)
A21: UC-17 | B21: Required work before a move | C21: Phase 1C | D21: Sales | E21: Attempt a stage move → outstanding items listed → resolve inline → original action resumes | F21: 1C-33, 1C-32 | G21: 2 | H21: =COUNTIFS('Phase 1C'!$A$5:$A$40,"1C-33",'Phase 1C'!$K$5:$K$40,"Pass")+COUNTIFS('Phase 1C'!$A$5:$A$40,"1C-32",'Phase 1C'!$K$5:$K$40,"Pass") | I21: =IF(H21=G21,"Fully covered",IF(H21=0,"Not started","Partial — "&H21&" of "&G21)
A22: UC-18 | B22: Right pipeline every time | C22: Phase 1C | D22: Admin | E22: Deal on a non-Sales pipeline → open its Automations from the Deal page → correct pipeline opens | F22: 1C-05, 1C-03, 1C-04 | G22: 3 | H22: =COUNTIFS('Phase 1C'!$A$5:$A$40,"1C-05",'Phase 1C'!$K$5:$K$40,"Pass")+COUNTIFS('Phase 1C'!$A$5:$A$40,"1C-03",'Phase 1C'!$K$5:$K$40,"Pass")+COUNTIFS('Phase 1C'!$A$5:$A$40,"1C-04",'Phase 1C'!$K$5:$K$40,"Pass") | I22: =IF(H22=G22,"Fully covered",IF(H22=0,"Not started","Partial — "&H22&" of "&G22)
A24: Journeys fully covered | C24: =COUNTIF(I5:I22,"Fully covered")&" of "&COUNTA(I5:I22)

Sheet Phase 1A
A1: QA checklist — Phase 1A
A2: CRM foundation — records, stage logic, alternatives, change orders, value, visibility and tenancy.
A3: Fill in from Status onwards. Everything to the left describes the test.
A4: ID | B4: Release | C4: Applies from | D4: Area | E4: Pri | F4: Method | G4: Precondition | H4: Steps | I4: Expected result | J4: Traces to | K4: Status | L4: Actual result | M4: Build | N4: Environment | O4: Browser / device | P4: Test data | Q4: Evidence link | R4: Defect ID | S4: Waiver approved by | T4: Tester | U4: Date | V4: Notes
A5: 1A-01 | B5: Phase 1A | C5: Phase 1A | D5: Lead | E5: P1 | F5: Manual | G5: A customer named Hillside Residence already exists. | H5: Create a Lead for 'Hillside Residence'. | I5: Possible matches are shown before saving. The user must pick one or explicitly create new. No customer is created silently. | J5: FR-27 / AC-LEAD-01 | K5: Not run
A6: 1A-02 | B6: Phase 1A | C6: Phase 1A | D6: Lead | E6: P1 | F6: Manual | G6: An open Lead exists. | H6: Convert the Lead to a Deal. | I6: Exactly one Deal is created, in Qualified. The Lead becomes converted and read-only. | J6: FR-28 / AC-LEAD-02, AC-LEAD-03 | K6: Not run
A7: 1A-03 | B7: Phase 1A | C7: Phase 1A | D7: Lead | E7: P2 | F7: Manual | G7: A converted Lead exists. | H7: Attempt to convert it again. | I7: Rejected. A message names the Deal that already exists and links to it. No second Deal is created. | J7: AC-LEAD-03 | K7: Not run
A8: 1A-04 | B8: Phase 1A | C8: Phase 1A | D8: Lead | E8: P1 | F8: Manual | G8: An open Lead exists. | H8: Discard it without choosing a reason. | I8: Discard is refused. The reason field is marked required and the Lead stays open until one is chosen. | J8: AC-LEAD-04 | K8: Not run
A9: 1A-05 | B9: Phase 1A | C9: Phase 1A | D9: Lead | E9: P1 | F9: Manual | G9: An open Lead exists. | H9: Try every route to attach a quote to the Lead. | I9: No route exists — not from the Lead, not from the quote list, not by direct URL. A quote can only attach to a Deal. | J9: FR-26 / AC-LEAD-05 | K9: Not run
A10: 1A-06 | B10: Phase 1A | C10: Phase 1A | D10: Lead | E10: P2 | F10: Manual | G10: Leads across several companies. | H10: Filter the Lead inbox by company. | I10: Only Leads whose owning company matches the filter are listed. The count in the header matches the rows shown. | J10: FR-38 / C15 | K10: Not run
A11: 1A-07 | B11: Phase 1A | C11: Phase 1A | D11: Resolver | E11: P1 | F11: Automated | G11: A Deal with no related quote. | H11: Inspect the Deal stage. | I11: The Deal reads Qualified. No stage control is offered to the user. | J11: AC-DEAL-01 | K11: Not run
A12: 1A-08 | B12: Phase 1A | C12: Phase 1A | D12: Resolver | E12: P1 | F12: Automated | G12: A Deal in Qualified. | H12: Create the first related quote. | I12: The Deal moves to In Progress. No screen offers a manual move. | J12: Locked rule 1 | K12: Not run
A13: 1A-09 | B13: Phase 1A | C13: Phase 1A | D13: Resolver | E13: P1 | F13: Automated | G13: A draft quote; quote review enabled. | H13: Submit the quote for review. | I13: The Deal moves to In Review, the history records the trigger, and no other Deal is affected. | J13: AC-DEAL-01 | K13: Not run
A14: 1A-10 | B14: Phase 1A | C14: Phase 1A | D14: Resolver | E14: P1 | F14: Automated | G14: A quote in review. | H14: Reviewer passes the quote. | I14: The Deal moves to Passed Review and the history records who passed it and when. | J14: AC-DEAL-01 | K14: Not run
A15: 1A-11 | B15: Phase 1A | C15: Phase 1A | D15: Resolver | E15: P1 | F15: Automated | G15: A quote that passed review. | H15: Send the quote to the client. | I15: The Deal moves to Sent and the sent date is recorded against the quote. | J15: AC-DEAL-01 | K15: Not run
A16: 1A-12 | B16: Phase 1A | C16: Phase 1A | D16: Resolver | E16: P1 | F16: Automated | G16: Quote review DISABLED for the organisation. | H16: Send a quote directly from In Progress. | I16: The Deal moves straight to Sent. In Review and Passed Review never appear. | J16: A6 / FR-12 | K16: Not run
... A58: 1A-54 | B58: Phase 1A | C58: Phase 1A | D58: History | E58: P1 | F58: Manual | G58: A Deal that moved through several stages. | H58: Open the Deal history. | I58: Every protected transition recorded with its trigger; every backward correction records its reason. | J58: AC-DEAL-01 | K58: Not run

Sheet Phase 1B
A1: QA checklist — Phase 1B
A2: Managed recipes — settings without the canvas, versioning, idempotency, timed work, approvals and Deal-card output.
A3: Fill in from Status onwards. Everything to the left describes the test.
A4: ID | B4: Release | C4: Applies from | D4: Area | E4: Pri | F4: Method | G4: Precondition | H4: Steps | I4: Expected result | J4: Traces to | K4: Status | L4: Actual result | M4: Build | N4: Environment | O4: Browser / device | P4: Test data | Q4: Evidence link | R4: Defect ID | S4: Waiver approved by | T4: Tester | U4: Date | V4: Notes
A5: 1B-01 | B5: Phase 1B | C5: Phase 1B | D5: Recipe setup | E5: P1 | F5: Manual | G5: Phase 1B build. | H5: Enable a recipe and change owner, wait days and label. | I5: Every exposed setting can be changed and saved from the recipe form. The canvas is never opened, and the saved values are reflected the next time the recipe runs. | J5: FR-02 | K5: Not run
A6: 1B-02 | B6: Phase 1B | C6: Phase 1B | D6: Recipe setup | E6: P1 | F6: Manual | G6: Creating a recipe. | H6: Save without choosing a company scope. | I6: Blocked. Scope is required and defaults to All Companies. | J6: FR-09 / AC-BLD-04 | K6: Not run
A7: 1B-03 | B7: Phase 1B | C7: Phase 1B | D7: Recipe setup | E7: P2 | F7: Manual | G7: A recipe with company scope set. | H7: Check every surface that lists it. | I7: Scope visible in list, editor, comparison, publish and history. | J7: FR-10 | K7: Not run
A8: 1B-04 | B8: Phase 1B | C8: Phase 1B | D8: Recipe setup | E8: P1 | F8: Automated | G8: A recipe scoped to one company. | H8: Trigger the matching event in another company. | I8: The recipe does not run. No note, task or notification is created, and nothing is written to that Deal's history. | J8: FR-15 / AC-RUN-06 | K8: Not run
A9: 1B-05 | B9: Phase 1B | C9: Phase 1B | D9: Versioning | E9: P1 | F9: Automated | G9: A published recipe. | H9: Change a setting and save without publishing. | I9: The live version keeps running. The change is held as a draft. | J9: FR-11 / AC-BLD-08 | K9: Not run
A10: 1B-06 | B10: Phase 1B | C10: Phase 1B | D10: Versioning | E10: P1 | F10: Automated | G10: A recipe with work already waiting. | H10: Publish a new version. | I10: Work in flight finishes on the version it started with. | J10: A15 | K10: Not run
A11: 1B-07 | B11: Phase 1B | C11: Phase 1B | D11: Versioning | E11: P1 | F11: Manual | G11: Phase 1B build. | H11: Restart the server, then read a saved recipe and its versions. | I11: The recipe and all its versions load exactly as before the restart. Nothing depended on the browser, and any work that was waiting is still waiting. | J11: FR-40 | K11: Not run
A12: 1B-08 | B12: Phase 1B | C12: Phase 1B | D12: Idempotency | E12: P1 | F12: Automated | G12: A recipe creating a note, a next action and a file request. | H12: Replay the same source event three times. | I12: Exactly one note, one next action and one file request exist. The run history shows three receipts of the same event and two of them recorded as already handled. | J12: FR-21 / AC-RUN-04 | K12: Not run
A13: 1B-09 | B13: Phase 1B | C13: Phase 1B | D13: Timed work | E13: P1 | F13: Automated | G13: Sent quote follow-up, three working days. | H13: Send a quote on a Friday. | I13: Fires the following Wednesday, counting working days only. | J13: FR-36 | K13: Not run
A14: 1B-10 | B14: Phase 1B | C14: Phase 1B | D14: Timed work | E14: P1 | F14: Automated | G14: A recipe waiting on a Deal. | H14: Move the Deal out of the stage before the wait ends. | I14: The pending run is cancelled or revalidated; it does not fire against the wrong stage. | J14: FR-36 | K14: Not run
A15: 1B-11 | B15: Phase 1B | C15: Phase 1B | D15: Timed work | E15: P2 | F15: Automated | G15: A wait spanning a daylight-saving change. | H15: Let the wait elapse. | I15: It fires at the intended local time, not an hour early or late. | J15: FR-36 | K15: Not run
A16: 1B-12 | B16: Phase 1B | C16: Phase 1B | D16: Timed work | E16: P1 | F16: Manual | G16: Event-driven recipes only; work queue not yet built. | H16: Trigger a quote-sent recipe. | I16: It runs. Event-driven recipes are not blocked by the queue. | J16: FR-36 | K16: Not run
... A29: 1B-25 | B29: Phase 1B | C29: Phase 1B | D29: Deal card | E29: P1 | F29: Manual | G29: An outstanding file request on a Deal card. | H29: Upload the matching file. | I29: Card, activity, focus and history all clear or update together. | J29: FR-20 | K29: Not run

Sheet Recipe coverage
A1: Recipe coverage matrix
A2: Each of the twelve ready-made recipes, against nine checks. Every cell is a test result.
A4: ID | B4: Recipe | C4: Stage | D4: Kind | E4: Correct trigger | F4: Rule Yes path | G4: Rule No path | H4: Correct action | I4: Company scope | J4: Active / Inactive | K4: Output in right place | L4: History entry | M4: Retry no duplicate | N4: Notes
A5: RC-01 | B5: Qualified first next action | C5: Qualified | D5: Event | E5: Not run | F5: Not run | G5: Not run | H5: Not run | I5: Not run | J5: Not run | K5: Not run | L5: Not run | M5: Not run
A6: RC-02 | B6: Qualified inactivity reminder | C6: Qualified | D6: Timed | E6: Not run | F6: Not run | G6: Not run | H6: Not run | I6: Not run | J6: Not run | K6: Not run | L6: Not run | M6: Not run
A7: RC-03 | B7: Site visit & pre-quote readiness | C7: Qualified | D7: Event | E7: Not run | F7: Not run | G7: Not run | H7: Not run | I7: Not run | J7: Not run | K7: Not run | L7: Not run | M7: Not run
A8: RC-04 | B8: Quote build and scope-of-work checks | C8: In Progress | D8: Event | E8: Not run | F8: Not run | G8: Not run | H8: Not run | I8: Not run | J8: Not run | K8: Not run | L8: Not run | M8: Not run
A9: RC-05 | B9: Internal quote review | C9: In Review | D9: Event | E9: Not run | F9: Not run | G9: Not run | H9: Not run | I9: Not run | J9: Not run | K9: Not run | L9: Not run | M9: Not run
A10: RC-06 | B10: Ready-to-send check | C10: Passed Review | D10: Event | E10: Not run | F10: Not run | G10: Not run | H10: Not run | I10: Not run | J10: Not run | K10: Not run | L10: Not run | M10: Not run
A11: RC-07 | B11: High-value approval | C11: Passed Review | D11: Event | E11: Not run | F11: Not run | G11: Not run | H11: Not run | I11: Not run | J11: Not run | K11: Not run | L11: Not run | M11: Not run
A12: RC-08 | B12: Sent quote follow-up | C12: Sent | D12: Timed | E12: Not run | F12: Not run | G12: Not run | H12: Not run | I12: Not run | J12: Not run | K12: Not run | L12: Not run | M12: Not run
A13: RC-09 | B13: Quote expiry reminder | C13: Sent | D13: Timed | E13: Not run | F13: Not run | G13: Not run | H13: Not run | I13: Not run | J13: Not run | K13: Not run | L13: Not run | M13: Not run
A14: RC-10 | B14: Won Deal handoff | C14: Won | D14: Event | E14: Not run | F14: Not run | G14: Not run | H14: Not run | I14: Not run | J14: Not run | K14: Not run | L14: Not run | M14: Not run
A15: RC-11 | B15: Accepted quote to draft invoice | C15: Won | D15: Event | E15: Not run | F15: Not run | G15: Not run | H15: Not run | I15: Not run | J15: Not run | K15: Not run | L15: Not run | M15: Not run
A16: RC-12 | B16: Lost Deal reason follow-up | C16: Lost | D16: Event | E16: Not run | F16: Not run | G16: Not run | H16: Not run | I16: Not run | J16: Not run | K16: Not run | L16: Not run | M16: Not run
A18: Cells outstanding | B18: =COUNTIF(E5:M16,"Fail")+COUNTIF(E5:M16,"Blocked")+COUNTIF(E5:M16,"Not run")

Sheet Phase 1C
A1: QA checklist — Phase 1C
A2: Advanced builder — navigation, catalogue, editing flow, simulator, publishing, state and required work.
A3: Fill in from Status onwards. Everything to the left describes the test.
A4: ID | B4: Release | C4: Applies from | D4: Area | E4: Pri | F4: Method | G4: Precondition | H4: Steps | I4: Expected result | J4: Traces to | K4: Status | L4: Actual result | M4: Build | N4: Environment | O4: Browser / device | P4: Test data | Q4: Evidence link | R4: Defect ID | S4: Waiver approved by | T4: Tester | U4: Date | V4: Notes
A5: 1C-01 | B5: Phase 1C | C5: Phase 1C | D5: Creation | E5: P1 | F5: Manual | G5: Phase 1C build. | H5: Open Create Automation. | I5: Exactly two routes: start from a recipe, or start from scratch. | J5: FR-01 / AC-BLD-03 | K5: Not run
A6: 1C-02 | B6: Phase 1C | C6: Phase 1C | D6: Creation | E6: P1 | F6: Manual | G6: A pipeline with no Automations. | H6: Open it. | I6: Opens to an empty state that explains the situation and offers Create Automation. | J6: FR-23 / AC-BLD-02 | K6: Not run
A7: 1C-03 | B7: Phase 1C | C7: Phase 1C | D7: Navigation | E7: P1 | F7: Manual | G7: Deals shows more than one pipeline, including a non-Sales one. | H7: Open the Automation pipeline chooser. | I7: Every pipeline that appears in Deals is listed in the chooser, with the same names and in a predictable order. | J7: AC-BLD-01 | K7: Not run
A8: 1C-04 | B8: Phase 1C | C8: Phase 1C | D8: Navigation | E8: P1 | F8: Manual | G8: A non-Sales pipeline exists. | H8: Choose it from the chooser. | I8: That pipeline opens. It never falls back to Sales Pipeline. | J8: AC-BLD-01 | K8: Not run
A9: 1C-05 | B9: Phase 1C | C9: Phase 1C | D9: Navigation | E9: P1 | F9: Manual | G9: A Deal belonging to a non-Sales pipeline. | H9: Click the Automation status control on the Deal page. | I9: That Deal's own pipeline opens, focused on the right stage. It never falls back to Sales Pipeline. | J9: AC-BLD-01 | K9: Not run
A10: 1C-06 | B10: Phase 1C | C10: Phase 1C | D10: Catalogue | E10: P1 | F10: Automated | G10: The builder open in each of the seven stages. | H10: Compare the offered blocks. | I10: The shared core is identical in all seven. Only quote-specific additions differ. | J10: FR-06 / AC-BLD-05 | K10: Not run
A11: 1C-07 | B11: Phase 1C | C11: Phase 1C | D11: Catalogue | E11: P1 | F11: Manual | G11: The builder open in In Progress. | H11: Look for a Lead-only trigger. | I11: The incompatible trigger is visible but struck through and cannot be selected. A short reason explains why it does not apply here. | J11: FR-11 / AC-BLD-06 | K11: Not run
A12: 1C-08 | B12: Phase 1C | C12: Phase 1C | D12: Catalogue | E12: P1 | F12: Manual | G12: The builder on any stage. | H12: Try to add an action that sets a Deal stage. | I12: No such action exists anywhere in the catalogue — not under a different name, and not behind a search. | J12: FR-08 / AC-BLD-07 | K12: Not run
A13: 1C-09 | B13: Phase 1C | C13: Phase 1C | D13: Catalogue | E13: P1 | F13: Automated | G13: Phase 1C build. | H13: Inspect how the block list is produced. | I13: One shared source. No per-stage hard-coded lists; placement is not a permission key. | J13: FR-33 | K13: Not run
A14: 1C-10 | B14: Phase 1C | C14: Phase 1C | D14: Builder | E14: P2 | F14: Manual | G14: An Automation created from In Progress. | H14: Try to change its stage in the builder. | I14: The stage selector is read-only and shows why: the Automation was created from that stage. | J14: A9 | K14: Not run
A15: 1C-11 | B15: Phase 1C | C15: Phase 1C | D15: Editing | E15: P1 | F15: Manual | G15: A published Automation, nothing changed. | H15: Look at Save Draft. | I15: Disabled. Before & After shows 'no unpublished changes', not two identical panes. | J15: AC-BLD-11 | K15: Not run
A16: 1C-12 | B16: Phase 1C | C16: Phase 1C | D16: Editing | E16: P1 | F16: Manual | G16: A published Automation. | H16: Change one step. | I16: 'Unpublished changes' appears, and Before & After compares published with draft. | J16: AC-BLD-11 | K16: Not run
... A40: 1C-36 | B40: Phase 1C | C40: Phase 1C | D40: Handoff | E40: P2 | F40: Manual | G40: Phase 1C shipped. | H40: Open a recipe as an editable copy. | I40: The live recipe keeps running; the copy is independent and the move is stated as one-way. | J40: FR-04 | K40: Not run

Sheet Regression
A1: QA checklist — Regression
A2: The six rules that must not drift. Each states the earliest release it applies from.
A3: Fill in from Status onwards. Everything to the left describes the test.
A4: ID | B4: Release | C4: Applies from | D4: Area | E4: Pri | F4: Method | G4: Precondition | H4: Steps | I4: Expected result | J4: Traces to | K4: Status | L4: Actual result | M4: Build | N4: Environment | O4: Browser / device | P4: Test data | Q4: Evidence link | R4: Defect ID | S4: Waiver approved by | T4: Tester | U4: Date | V4: Notes
A5: REG-01 | B5: Regression | C5: Phase 1A | D5: Locked rule 1 | E5: P1 | F5: Automated | G5: Any release. | H5: Create the first related quote on a Qualified Deal. | I5: The Deal moves to In Progress. | J5: Locked rule 1 | K5: Not run
A6: REG-02 | B6: Regression | C6: Phase 1A | D6: Locked rule 2 | E6: P1 | F6: Automated | G6: Any release. | H6: Accept any one relevant quote. | I6: The Deal becomes Won. Remaining groups change value only. | J6: Locked rule 2 | K6: Not run
A7: REG-03 | B7: Regression | C7: Phase 1A | D7: Locked rule 3 | E7: P1 | F7: Automated | G7: Any release. | H7: Reach a state where no viable quote remains. | I7: Lost is derived. Sales supplies the reason and cannot change the outcome. | J7: Locked rule 3 | K7: Not run
A8: REG-04 | B8: Regression | C8: Phase 1C | D8: Locked rule 4 | E8: P1 | F8: Manual | G8: Authoring exists. | H8: Publish a valid change without testing. | I8: Allowed. Only a real conflict blocks publishing. | J8: Locked rule 4 | K8: Not run
A9: REG-05 | B9: Regression | C9: Phase 2 | D9: Locked rule 5 | E9: P1 | F9: Manual | G9: Custom stages exist. | H9: Place the same custom stage in different lifecycle gaps. | I9: The core block library offered is identical every time. | J9: Locked rule 5 | K9: Not run
A10: REG-06 | B10: Regression | C10: Phase 1A | D10: Locked rule 6 | E10: P1 | F10: Automated | G10: Any release. | H10: Search the action catalogue for approve, send, accept, Won or Lost. | I10: None exists as an action. | J10: Locked rule 6 | K10: Not run

Sheet Non-functional
A1: QA checklist — Non-functional
A2: Concurrency, event ordering, partial failure, performance, permissions, accessibility, browsers, audit and recovery.
A3: Fill in from Status onwards.
A4: ID | B4: Release | C4: Applies from | D4: Area | E4: Pri | F4: Method | G4: Precondition | H4: Steps | I4: Expected result | J4: Traces to | K4: Status | L4: Actual result | M4: Build | N4: Environment | O4: Browser / device | P4: Test data | Q4: Evidence link | R4: Defect ID | S4: Waiver approved by | T4: Tester | U4: Date | V4: Notes
A5: NF-01 | B5: All | C5: Phase 1A | D5: Concurrency | E5: P1 | F5: Manual | G5: Two users editing the same Automation. | H5: Both save a draft, then both publish within seconds of each other. | I5: One publish succeeds; the second is refused with a message that the version moved on, and offers to reload. No silent overwrite, and the published version matches one editor's intent exactly. | J5: FR-14 | K5: Not run
A6: NF-02 | B6: All | C6: Phase 1A | D6: Concurrency | E6: P1 | F6: Manual | G6: Two users on the same Deal. | H6: Both accept a different quote in the same alternative group at the same time. | I6: Exactly one acceptance wins. The other is refused with a clear reason, and the Deal has one winner, not two. | J6: AC-DEAL-07 | K6: Not run
A7: NF-03 | B7: All | C7: Phase 1A | D7: Event order | E7: P1 | F7: Automated | G7: A Deal with one quote. | H7: Deliver the quote-sent and quote-accepted events out of order. | I7: The Deal ends in the correct final stage regardless of arrival order, and history records the true sequence of quote events. | J7: FR-16 | K7: Not run
A8: NF-04 | B8: All | C8: Phase 1A | D8: Event order | E8: P1 | F8: Automated | G8: A recipe listening to a quote event. | H8: Deliver the same event twice, ten minutes apart. | I8: The second delivery is recognised as already handled. Nothing is created twice. | J8: FR-21 | K8: Not run
A9: NF-05 | B9: All | C9: Phase 1A | D9: Event order | E9: P2 | F9: Automated | G9: An event delayed by an hour in the queue. | H9: Let it arrive late. | I9: It is processed against the Deal's state at the time of processing, and the delay is visible in the run record. | J9: FR-36 | K9: Not run
A10: NF-06 | B10: All | C10: Phase 1A | D10: Partial failure | E10: P1 | F10: Manual | G10: A recipe with three actions; the second one fails. | H10: Trigger it. | I10: The failure is recorded against the run with the step named. Completed actions are not rolled back silently, and a retry does not repeat the ones that already succeeded. | J10: FR-21 | K10: Not run
A11: NF-07 | B11: All | C11: Phase 1A | D11: Partial failure | E11: P1 | F11: Manual | G11: A recipe that failed. | H11: Open the run history. | I11: The failure, its reason, its timestamp and the affected step are all visible without needing server logs. | J11: FR-21 | K11: Not run
A12: NF-08 | B12: All | C12: Phase 1A | D12: Performance | E12: P2 | F12: Manual | G12: An organisation with several thousand Deals and quotes. | H12: Open the pipeline board and the Deal list. | I12: Both render within an acceptable time and the stage counts are correct. Note the measured time in Actual result. | J12: — | K12: Not run
A13: NF-09 | B13: All | C13: Phase 1A | D13: Performance | E13: P2 | F13: Manual | G13: A Deal carrying a long activity history. | H13: Open the Deal. | I13: The page opens without freezing and the timeline pages or scrolls rather than loading everything at once. | J13: — | K13: Not run
A14: NF-10 | B14: All | C14: Phase 1A | D14: Permissions | E14: P1 | F14: Manual | G14: Roles with and without CRM access. | H14: Sign in as each role and attempt to view and edit Leads, Deals and Automations. | I14: Each role sees and can change only what its permissions allow. A role without access gets a clear refusal, not an empty screen. | J14: FR-38 | K14: Not run
A15: NF-11 | B15: All | C15: Phase 1A | D15: Permissions | E15: P1 | F15: Manual | G15: A user limited to one company. | H15: Attempt to open a Deal from another company by direct URL. | I15: Refused. The record is not rendered and nothing about it leaks in the error. | J15: FR-38 | K15: Not run
A16: NF-12 | B16: All | C16: Phase 1A | D16: Accessibility | E16: P2 | F16: Manual | G16: The required-work dialog open. | H16: Navigate it with the keyboard only. | I16: Focus moves into the dialog, stays trapped inside it, every control is reachable, and Escape closes it returning focus to the trigger. | J16: — | K16: Not run
... A20: NF-16 | B20: All | C20: Phase 1A | D20: Recovery | E20: P1 | F20: Manual | G20: Drafts saved and timed work pending. | H20: Restart the server. | I20: Drafts, pending runs and published versions all survive. Pending work resumes on the version it started with. | J20: FR-40 | K20: Not run

Sheet Test Runs
A1: Test runs
A2: One row per execution cycle. The go / no-go decision belongs here, with who made it.
A4: Run | B4: Release | C4: Build / commit | D4: Environment | E4: Browser / device | F4: Scope | G4: Tester | H4: Start | I4: End | J4: Pass | K4: Fail | L4: Blocked | M4: N/A | N4: Not run | O4: Go / no-go | P4: Decided by | Q4: Notes
A5: R-01 | B5: Phase 1A | C5: 1A-rc3 | D5: Staging | E5: Chrome 141 / macOS | F5: Full Phase 1A + applicable Regression | G5: KW | H5: 2026-09-01 | I5: 2026-09-04 | J5: 48 | K5: 3 | L5: 1 | M5: 2 | N5: 0 | O5: No-go | P5: CTO | Q5: Two S2 defects open — WQ-1183, WQ-1190
A27: Row 5 is a worked example — overwrite or delete it before the first real run.
